Workbook

Sheet Caratula
G4: Sección: 22312
A9: Curso: Contabilidad General | G9: Ciclo: 4to ciclo
A11: Docente: Velazco Galindo, Angela Giovana
A13: INTEGRANTES
A14: Fernández Kana Érick | H14: 1
A15: Huamani Luque Nick Alexander Walter | H15: 1
A16: Poma Aquino Roy Anthony | H16: 1

Sheet Libros Contables
A1: COMERCIAL EL ANDINO S.A.C. – Libros contables: parámetros y sustento de operaciones
A3: RUC 20601234567 |Período: octubre 2026 | Moneda: soles (S/)
A5: A. PARÁMETROS DEL ENUNCIADO
A6: Concepto | B6: Valor | C6: Unidad | D6: Fuente / nota
A7: Tasa del IGV | B7: 0.18 | C7: % | D7: Enunciado: operaciones sujetas al IGV del 18% donde corresponda
A8: Aporte en efectivo (depositado en banco) | B8: 50000 | C8: S/ | D8: Operación 1
A9: Aporte en equipos de cómputo | B9: 12000 | C9: S/ | D9: Operación 1; el valor aportado es el costo del activo
A10: Alquiler mensual (valor de venta, sin IGV) | B10: 2000 | C10: S/ | D10: Operación 2
A11: Meses de alquiler pagados por adelantado | B11: 3 | C11: meses | D11: Operación 2: octubre, noviembre y diciembre
A12: Unidades compradas (licuadoras industriales) | B12: 100 | C12: unid. | D12: Operación 3; factura 001-0465
A13: Costo unitario de compra (sin IGV) | B13: 200 | C13: S/ | D13: Operación 3
A14: % del inventario vendido | B14: 0.6 | C14: % | D14: Operación 4
A15: Precio de venta unitario (sin IGV) | B15: 400 | C15: S/ | D15: Operación 4. Supuesto: S/ 400 es valor de venta y el IGV se suma
A16: % de la venta cobrado al contado (banco) | B16: 0.5 | C16: % | D16: Operación 4; el resto es crédito a 30 días
A17: Unidades deterioradas por filtración de agua | B17: 5 | C17: unid. | D17: Operación 6
A18: Desvalorización provisionada por gerencia | B18: 1000 | C18: S/ | D18: Operación 6
A19: Vida útil del equipo de cómputo | B19: 4 | C19: años | D19: Operación 7. Supuesto: línea recta y sin valor residual
A21: B. CÁLCULOS DE SOPORTE (todos con fórmula)
A22: Concepto | B22: Importe | C22: Unidad | D22: Cálculo operativo
A23: Capital social total | B23: =$B$8+$B$9 -> 62000 | C23: S/ | D23: Aporte en efectivo + aporte en equipos
A24: Alquiler adelantado (valor de venta) | B24: =$B$10*$B$11 -> 6000 | C24: S/ | D24: Alquiler mensual × meses pagados
A25: IGV del alquiler (crédito fiscal) | B25: =$B$24*$B$7 -> 1080 | C25: S/ | D25: Valor de venta × 18%
A26: Total pagado por transferencia bancaria | B26: =$B$24+$B$25 -> 7080 | C26: S/ | D26: Valor + IGV; el enunciado indica S/ 7,080
A27: Valor de la compra de mercaderías | B27: =$B$12*$B$13 -> 20000 | C27: S/ | D27: Unidades × costo unitario
A28: IGV de la compra (crédito fiscal) | B28: =$B$27*$B$7 -> 3600 | C28: S/ | D28: Valor de compra × 18%
A29: Total factura 001-0465 por pagar | B29: =$B$27+$B$28 -> 23600 | C29: S/ | D29: Valor + IGV
A30: Unidades vendidas | B30: =$B$12*$B$14 -> 60 | C30: unid. | D30: Unidades compradas × % vendido
A31: Valor de venta | B31: =$B$30*$B$15 -> 24000 | C31: S/ | D31: Unidades vendidas × precio unitario
A32: IGV de la venta (débito fiscal) | B32: =$B$31*$B$7 -> 4320 | C32: S/ | D32: Valor de venta × 18%
A33: Total de la venta (con IGV) | B33: =$B$31+$B$32 -> 28320 | C33: S/ | D33: Valor + IGV
A34: Cobro al contado en banco | B34: =$B$33*$B$16 -> 14160 | C34: S/ | D34: Total × % contado
A35: Saldo por cobrar a 30 días | B35: =$B$33-$B$34 -> 14160 | C35: S/ | D35: Total − cobro al contado
A36: Costo de ventas | B36: =$B$30*$B$13 -> 12000 | C36: S/ | D36: Unidades vendidas × costo unitario
A37: Unidades en almacén tras la venta | B37: =$B$12-$B$30 -> 40 | C37: unid. | D37: Compradas − vendidas
A38: Existencias finales al costo | B38: =$B$37*$B$13 -> 8000 | C38: S/ | D38: Unidades restantes × costo unitario
A39: Alquiler devengado de octubre | B39: =$B$10 -> 2000 | C39: S/ | D39: Un mes de alquiler (valor sin IGV)
A40: Depreciación anual | B40: =$B$9/$B$19 -> 3000 | C40: S/ | D40: Costo ÷ vida útil en años
A41: Depreciación mensual | B41: =$B$40/12 -> 250 | C41: S/ | D41: Depreciación anual ÷ 12
A42: IGV: saldo a favor (crédito − débito fiscal) | B42: =$B$25+$B$28-$B$32 -> 360 | C42: S/ | D42: IGV alquiler + IGV compra − IGV ventas
A43: Control: unid. deterioradas × costo unitario | B43: =$B$17*$B$13 -> 1000 | C43: S/ | D43: Debe coincidir con la provisión de gerencia
...

Sheet T Contables
A1: T CONTABLES
A4: 104 – Cuentas corrientes en instituciones financieras | F4: 1212 – Facturas, boletas y otros comprobantes por cobrar – Emitidas en cartera | K4: 201 – Mercaderías manufacturadas
A5: DEBE | C5: HABER | F5: DEBE | H5: HABER | K5: DEBE | M5: HABER
B6: ='Diario Simplificado'!$C$11 -> 50000 | D6: =-'Diario Simplificado'!$C$12 -> 7080 | G6: ='Diario Simplificado'!$D$14 -> 14160 | L6: ='Diario Simplificado'!$F$13 -> 20000 | N6: =-'Diario Simplificado'!$F$14 -> 12000
B7: ='Diario Simplificado'!$C$14 -> 14160
A9: Total | B9: =SUM(B6:B8) -> 64160 | D9: =SUM(D6:D8) -> 7080 | F9: Total | G9: =SUM(G6:G8) -> 14160 | I9: =SUM(I6:I8) -> 0 | K9: Total | L9: =SUM(L6:L8) -> 20000 | N9: =SUM(N6:N8) -> 12000
A10: S. deudor | B10: =MAX(B9-D9,0) -> 57080 | C10: S. acreedor | D10: =MAX(D9-B9,0) -> 0 | F10: S. deudor | G10: =MAX(G9-I9,0) -> 14160 | H10: S. acreedor | I10: =MAX(I9-G9,0) -> 0 | K10: S. deudor | L10: =MAX(L9-N9,0) -> 8000 | M10: S. acreedor | N10: =MAX(N9-L9,0) -> 0
A13: 291 – Desvalorización de existencias – Mercaderías | F13: 40111 – IGV – Cuenta propia | K13: 379 – Cargas diferidas
A14: DEBE | C14: HABER | F14: DEBE | H14: HABER | K14: DEBE | M14: HABER
D15: =-'Diario Simplificado'!$G$16 -> 1000 | G15: ='Diario Simplificado'!$J$12 -> 1080 | I15: =-'Diario Simplificado'!$K$14 -> 4320 | L15: ='Diario Simplificado'!$E$12 -> 6000 | N15: =-'Diario Simplificado'!$E$15 -> 2000
G16: ='Diario Simplificado'!$J$13 -> 3600
A18: Total | B18: =SUM(B15:B17) -> 0 | D18: =SUM(D15:D17) -> 1000 | F18: Total | G18: =SUM(G15:G17) -> 4680 | I18: =SUM(I15:I17) -> 4320 | K18: Total | L18: =SUM(L15:L17) -> 6000 | N18: =SUM(N15:N17) -> 2000
A19: S. deudor | B19: =MAX(B18-D18,0) -> 0 | C19: S. acreedor | D19: =MAX(D18-B18,0) -> 1000 | F19: S. deudor | G19: =MAX(G18-I18,0) -> 360 | H19: S. acreedor | I19: =MAX(I18-G18,0) -> 0 | K19: S. deudor | L19: =MAX(L18-N18,0) -> 4000 | M19: S. acreedor | N19: =MAX(N18-L18,0) -> 0
A22: 3361 – Equipos para procesamiento de información | F22: 3913 – Depreciación acumulada – Inmuebles, maquinaria y equipo | K22: 4212 – Facturas, boletas y otros comprobantes por pagar – Emitidas
A23: DEBE | C23: HABER | F23: DEBE | H23: HABER | K23: DEBE | M23: HABER
B24: ='Diario Simplificado'!$H$11 -> 12000 | I24: =-'Diario Simplificado'!$I$17 -> 250 | N24: =-'Diario Simplificado'!$L$13 -> 23600
A27: Total | B27: =SUM(B24:B26) -> 12000 | D27: =SUM(D24:D26) -> 0 | F27: Total | G27: =SUM(G24:G26) -> 0 | I27: =SUM(I24:I26) -> 250 | K27: Total | L27: =SUM(L24:L26) -> 0 | N27: =SUM(N24:N26) -> 23600
A28: S. deudor | B28: =MAX(B27-D27,0) -> 12000 | C28: S. acreedor | D28: =MAX(D27-B27,0) -> 0 | F28: S. deudor | G28: =MAX(G27-I27,0) -> 0 | H28: S. acreedor | I28: =MAX(I27-G27,0) -> 250 | K28: S. deudor | L28: =MAX(L27-N27,0) -> 0 | M28: S. acreedor | N28: =MAX(N27-L27,0) -> 23600
A31: 501 – Capital social | F31: 691 – Costo de ventas – Mercaderías | K31: 701 – Ventas – Mercaderías
A32: DEBE | C32: HABER | F32: DEBE | H32: HABER | K32: DEBE | M32: HABER
D33: =-'Diario Simplificado'!$M$11 -> 62000 | G33: ='Diario Simplificado'!$N$14 -> 12000 | N33: =-'Diario Simplificado'!$R$14 -> 24000
A36: Total | B36: =SUM(B33:B35) -> 0 | D36: =SUM(D33:D35) -> 62000 | F36: Total | G36: =SUM(G33:G35) -> 12000 | I36: =SUM(I33:I35) -> 0 | K36: Total | L36: =SUM(L33:L35) -> 0 | N36: =SUM(N33:N35) -> 24000
A37: S. deudor | B37: =MAX(B36-D36,0) -> 0 | C37: S. acreedor | D37: =MAX(D36-B36,0) -> 62000 | F37: S. deudor | G37: =MAX(G36-I36,0) -> 12000 | H37: S. acreedor | I37: =MAX(I36-G36,0) -> 0 | K37: S. deudor | L37: =MAX(L36-N36,0) -> 0 | M37: S. acreedor | N37: =MAX(N36-L36,0) -> 24000
A40: 634 – Gastos por servicios de terceros – Alquileres | F40: 681 – Depreciación de inmuebles, maquinaria y equipo | K40: 685 – Deterioro del valor de los activos (desvalorización de existencias)
A41: DEBE | C41: HABER | F41: DEBE | H41: HABER | K41: DEBE | M41: HABER
B42: ='Diario Simplificado'!$O$15 -> 2000 | G42: ='Diario Simplificado'!$P$17 -> 250 | L42: ='Diario Simplificado'!$Q$16 -> 1000
A45: Total | B45: =SUM(B42:B44) -> 2000 | D45: =SUM(D42:D44) -> 0 | F45: Total | G45: =SUM(G42:G44) -> 250 | I45: =SUM(I42:I44) -> 0 | K45: Total | L45: =SUM(L42:L44) -> 1000 | N45: =SUM(N42:N44) -> 0
A46: S. deudor | B46: =MAX(B45-D45,0) -> 2000 | C46: S. acreedor | D46: =MAX(D45-B45,0) -> 0 | F46: S. deudor | G46: =MAX(G45-I45,0) -> 250 | H46: S. acreedor | I46: =MAX(I45-G45,0) -> 0 | K46: S. deudor | L46: =MAX(L45-N45,0) -> 1000 | M46: S. acreedor | N46: =MAX(N45-L45,0) -> 0

Sheet Cuentas de Valuación
A1: CUENTAS DE VALUACIÓN Y AJUSTES
A4: 1. Desvalorización de existencias (cuenta 291) – NIC 2
A5: Concepto | B5: Importe / cantidad | C5: Explicación operativa
A6: Unidades compradas | B6: ='Libros Contables'!$B$12 -> 100 | C6: Operación 3
A7: Unidades vendidas | B7: ='Libros Contables'!$B$30 -> 60 | C7: Operación 4
A8: Unidades en almacén al 31/10 | B8: ='Libros Contables'!$B$37 -> 40 | C8: Compradas − vendidas
A9: Unidades deterioradas por filtración | B9: ='Libros Contables'!$B$17 -> 5 | C9: Detectadas en el inventario físico
A10: Costo unitario | B10: ='Libros Contables'!$B$13 -> 200 | C10: Costo de adquisición sin IGV
A11: Desvalorización según costo | B11: =B9*B10 -> 1000 | C11: Unidades deterioradas × costo unitario
A12: Desvalorización provisionada por gerencia | B12: ='Libros Contables'!$B$18 -> 1000 | C12: Importe registrado en la operación 6
A13: Diferencia de control | B13: =B12-B11 -> 0 | C13: Debe ser cero
A14: Mercaderías al costo (cuenta 201) | B14: ='T Contables'!$L$10 -> 8000 | C14: Saldo de la T contable de mercaderías
A15: (−) Desvalorización de existencias (291) | B15: =-'T Contables'!$D$19 -> -1000 | C15: Cuenta correctora de saldo acreedor
A16: Mercaderías netas en el balance | B16: =B14+B15 -> 7000 | C16: Valor en libros después de la desvalorización
A18: 2. Depreciación acumulada (cuenta 3913) – NIC 16
A19: Concepto | B19: Importe | C19: Explicación operativa
A20: Costo del equipo de cómputo | B20: ='Libros Contables'!$B$9 -> 12000 | C20: Valor aportado por los socios
A21: Vida útil (años) | B21: ='Libros Contables'!$B$19 -> 4 | C21: Dato del enunciado
A22: Depreciación anual | B22: =B20/B21 -> 3000 | C22: Línea recta, sin valor residual (supuesto)
A23: Depreciación mensual | B23: =B22/12 -> 250 | C23: Anual ÷ 12 meses
A24: Depreciación acumulada al 31/10/2026 | B24: ='T Contables'!$I$28 -> 250 | C24: Un mes de depreciación
A25: Valor neto en libros del equipo | B25: =B20-B24 -> 11750 | C25: Costo − depreciación acumulada
A27: Cronograma referencial de depreciación (inicio en octubre 2026)
A28: Año | B28: Meses | C28: Depreciación del año | D28: Depreciación acumulada | E28: Valor neto
A29: 2026 (oct–dic) | B29: 3 | C29: =B29*$B$23 -> 750 | D29: =SUM($C$29:C29) -> 750 | E29: =$B$20-D29 -> 11250
A30: 2027 | B30: 12 | C30: =B30*$B$23 -> 3000 | D30: =SUM($C$29:C30) -> 3750 | E30: =$B$20-D30 -> 8250
A31: 2028 | B31: 12 | C31: =B31*$B$23 -> 3000 | D31: =SUM($C$29:C31) -> 6750 | E31: =$B$20-D31 -> 5250
A32: 2029 | B32: 12 | C32: =B32*$B$23 -> 3000 | D32: =SUM($C$29:C32) -> 9750 | E32: =$B$20-D32 -> 2250
A33: 2030 (ene–sep) | B33: 9 | C33: =B33*$B$23 -> 2250 | D33: =SUM($C$29:C33) -> 12000 | E33: =$B$20-D33 -> 0
A34: Total | B34: =SUM(B29:B33) -> 48 | C34: =SUM(C29:C33) -> 12000
A36: 3. Cargas diferidas – alquiler adelantado (cuenta 379)
A37: Concepto | B37: Importe | C37: Explicación operativa
A38: Alquiler pagado por adelantado (sin IGV) | B38: ='Libros Contables'!$B$24 -> 6000 | C38: 3 meses × alquiler mensual
A39: (−) Gasto devengado en octubre | B39: =-'Libros Contables'!$B$39 -> -2000 | C39: Un mes de alquiler
A40: Saldo por devengar (nov–dic) | B40: =B38+B39 -> 4000 | C40: Se presenta como gasto pagado por anticipado
A41: Control: saldo de la T contable 379 | B41: ='T Contables'!$L$19 -> 4000 | C41: Debe coincidir con la línea anterior
A43: 4. IGV – cuenta propia (40111)
A44: Concepto | B44: Importe | C44: Explicación operativa
A45: Crédito fiscal por el alquiler | B45: ='Libros Contables'!$B$25 -> 1080 | C45: Operación 2
A46: Crédito fiscal por la compra de mercaderías | B46: ='Libros Contables'!$B$28 -> 3600 | C46: Operación 3
...

Sheet Diario Simplificado
A1: FORMATO 5.2: "LIBRO DIARIO - FORMATO SIMPLIFICADO"
A3: PERÍODO: | B3: OCTUBRE 2026
A4: RUC: | B4: 20601234567
A5: APELLIDOS Y NOMBRES, DENOMINACIÓN O RAZÓN SOCIAL:
B6: COMERCIAL EL ANDINO S.A.C.
A8: Fecha o período de la operación | B8: Descripción de la operación (glosa) | C8: ACTIVO (TABLA 9) | J8: PASIVO (TABLA 9) | M8: PATRIMONIO (TABLA 9) | N8: GASTOS (TABLA 9) | R8: INGRESOS (TABLA 9) | S8: Control (suma de la fila = 0)
C9: 104 | D9: 1212 | E9: 379 | F9: 201 | G9: 291 | H9: 3361 | I9: 3913 | J9: 40111 D | K9: 40111 H | L9: 4212 | M9: 501 | N9: 691 | O9: 634 | P9: 681 | Q9: 685 | R9: 701
C10: Cuentas corrientes | D10: Cuentas por cobrar comerc. | E10: Alquileres pagados x anticip. | F10: Mercaderías | G10: Desvalorización de existencias | H10: Equipos de cómputo | I10: Deprec. acum. de PPE | J10: IGV crédito fiscal (Debe) | K10: IGV débito fiscal (Haber) | L10: Facturas por pagar | M10: Capital social | N10: Costo de ventas | O10: Alquileres | P10: Deprec. de PPE | Q10: Desvalor. de existencias | R10: Ventas mercaderías
A11: 46296 | B11: Constitución de la empresa con aportes de los socios en efectivo y en equipos de cómputo. | C11: ='Libros Contables'!$B$8 -> 50000 | H11: ='Libros Contables'!$B$9 -> 12000 | M11: =-'Libros Contables'!$B$23 -> -62000 | S11: =ROUND(SUM(C11:R11),2) -> 0
A12: 46298 | B12: Pago adelantado del alquiler del local por 3 meses (oct–dic) más IGV, por transferencia bancaria. | C12: =-'Libros Contables'!$B$26 -> -7080 | E12: ='Libros Contables'!$B$24 -> 6000 | J12: ='Libros Contables'!$B$25 -> 1080 | S12: =ROUND(SUM(C12:R12),2) -> 0
A13: 46303 | B13: Compra al crédito de 100 licuadoras industriales, factura 001-0465. | F13: ='Libros Contables'!$B$27 -> 20000 | J13: ='Libros Contables'!$B$28 -> 3600 | L13: =-'Libros Contables'!$B$29 -> -23600 | S13: =ROUND(SUM(C13:R13),2) -> 0
A14: 46310 | B14: Venta a Comercial Lima del 60% del inventario (50% al contado en banco, 50% a 30 días) y su costo de ventas. | C14: ='Libros Contables'!$B$34 -> 14160 | D14: ='Libros Contables'!$B$35 -> 14160 | F14: =-'Libros Contables'!$B$36 -> -12000 | K14: =-'Libros Contables'!$B$32 -> -4320 | N14: ='Libros Contables'!$B$36 -> 12000 | R14: =-'Libros Contables'!$B$31 -> -24000 | S14: =ROUND(SUM(C14:R14),2) -> 0
A15: 46326 | B15: Devengo del gasto de alquiler del mes de octubre. | E15: =-'Libros Contables'!$B$39 -> -2000 | O15: ='Libros Contables'!$B$39 -> 2000 | S15: =ROUND(SUM(C15:R15),2) -> 0
A16: 46326 | B16: Provisión por desvalorización de 5 unidades deterioradas por filtración de agua. | G16: =-'Libros Contables'!$B$18 -> -1000 | Q16: ='Libros Contables'!$B$18 -> 1000 | S16: =ROUND(SUM(C16:R16),2) -> 0
A17: 46326 | B17: Depreciación mensual del equipo de cómputo (S/ 12,000, vida útil 4 años). | I17: =-'Libros Contables'!$B$41 -> -250 | P17: ='Libros Contables'!$B$41 -> 250 | S17: =ROUND(SUM(C17:R17),2) -> 0
A19: TOTALES (saldo neto de cada columna) | C19: =SUM(C11:C17) -> 57080 | D19: =SUM(D11:D17) -> 14160 | E19: =SUM(E11:E17) -> 4000 | F19: =SUM(F11:F17) -> 8000 | G19: =SUM(G11:G17) -> -1000 | H19: =SUM(H11:H17) -> 12000 | I19: =SUM(I11:I17) -> -250 | J19: =SUM(J11:J17) -> 4680 | ... R19: =SUM(R11:R17) -> -24000 | S19: =ROUND(SUM(S11:S17),2) -> 0
A20: Total movimientos al DEBE | C20: =SUMIF(C11:C17,">0") -> 64160 | D20: =SUMIF(D11:D17,">0") -> 14160 | E20: =SUMIF(E11:E17,">0") -> 6000 | F20: =SUMIF(F11:F17,">0") -> 20000 | G20: =SUMIF(G11:G17,">0") -> 0 | H20: =SUMIF(H11:H17,">0") -> 12000 | I20: =SUMIF(I11:I17,">0") -> 0 | J20: =SUMIF(J11:J17,">0") -> 4680 | ... R20: =SUMIF(R11:R17,">0") -> 0 | S20: =SUM(C20:R20) -> 136250
A21: Total movimientos al HABER | C21: =-SUMIF(C11:C17,"<0") -> 7080 | D21: =-SUMIF(D11:D17,"<0") -> 0 | E21: =-SUMIF(E11:E17,"<0") -> 2000 | F21: =-SUMIF(F11:F17,"<0") -> 12000 | G21: =-SUMIF(G11:G17,"<0") -> 1000 | H21: =-SUMIF(H11:H17,"<0") -> 0 | I21: =-SUMIF(I11:I17,"<0") -> 250 | J21: =-SUMIF(J11:J17,"<0") -> 0 | ... R21: =-SUMIF(R11:R17,"<0") -> 24000 | S21: =SUM(C21:R21) -> 136250
A22: =IF(AND(ROUND(S20-S21,2)=0,ROUND(S19,2)=0),"✔ LIBRO DIARIO CUADRADO: Total Debe = Total Haber","✘ REVISAR: el libro diario no cuadra") -> ✔ LIBRO DIARIO CUADRADO: Total Debe = Total Haber

Sheet Estados Financieros
A1: COMERCIAL EL ANDINO S.A.C.
A2: RUC 20601234567
A4: ESTADO DE RESULTADOS (por función) – del 01/10/2026 al 31/10/2026
A5: Concepto | B5: Detalle | C5: Total
A6: Ventas netas | C6: ='T Contables'!$N$37 -> 24000
A7: (−) Costo de ventas | C7: =-'T Contables'!$G$37 -> -12000
A8: UTILIDAD BRUTA | C8: =C6+C7 -> 12000
A9: Gastos operativos
A10: Gastos de alquiler | B10: =-'T Contables'!$B$46 -> -2000
A11: Depreciación del equipo de cómputo | B11: =-'T Contables'!$G$46 -> -250
A12: Desvalorización de existencias | B12: =-'T Contables'!$L$46 -> -1000
A13: Total gastos operativos | C13: =SUM(B10:B12) -> -3250
A14: UTILIDAD OPERATIVA | C14: =C8+C13 -> 8750
A15: RESULTADO DEL EJERCICIO (antes de impuesto a la renta) | C15: =C14 -> 8750
A17: ESTADO DE SITUACIÓN FINANCIERA – al 31/10/2026
A18: Concepto | B18: Detalle | C18: Total
A19: ACTIVO
A20: Activo corriente
A21: Efectivo y equivalentes de efectivo (104) | B21: ='T Contables'!$B$10 -> 57080
A22: Cuentas por cobrar comerciales (1212) | B22: ='T Contables'!$G$10 -> 14160
A23: Mercaderías al costo (201) | B23: ='T Contables'!$L$10 -> 8000
A24: (−) Desvalorización de existencias (291) | B24: =-'T Contables'!$D$19 -> -1000
A25: Crédito fiscal IGV (40111) | B25: ='T Contables'!$G$19 -> 360
A26: Gastos pagados por anticipado – alquiler (379) | B26: ='T Contables'!$L$19 -> 4000
A27: Total activo corriente | C27: =SUM(B21:B26) -> 82600
A28: Activo no corriente
A29: Equipos de cómputo al costo (3361) | B29: ='T Contables'!$B$28 -> 12000
A30: (−) Depreciación acumulada (3913) | B30: =-'T Contables'!$I$28 -> -250
A31: Total activo no corriente | C31: =SUM(B29:B30) -> 11750
A32: TOTAL ACTIVO | C32: =C27+C31 -> 94350
A34: PASIVO
A35: Cuentas por pagar comerciales – facturas por pagar (4212) | B35: ='T Contables'!$N$28 -> 23600
A36: TOTAL PASIVO CORRIENTE | C36: =SUM(B35:B35) -> 23600
A38: PATRIMONIO
A39: Capital social (501) | B39: ='T Contables'!$D$37 -> 62000
A40: Resultado del ejercicio | B40: =C15 -> 8750
A41: TOTAL PATRIMONIO | C41: =SUM(B39:B40) -> 70750
A42: TOTAL PASIVO Y PATRIMONIO | C42: =C36+C41 -> 94350
A44: Control: Activo − (Pasivo + Patrimonio) | C44: =C32-C42 -> 0

Sheet Conclusiones
A1: CONCLUSIONES
A4: 1 | B4: ="El libro diario registra "&COUNT('Diario Simplificado'!A11:A17)&" operaciones con partida doble. Total Debe S/ "&TEXT('Diario Simplificado'!S20,"#,##0.00")&" = total Haber S/ "&TEXT('Diario Simplificado'!S21,"#,##0.00")&"." -> El libro diario registra 7 operaciones con partida doble. Total Debe S/ 136,250.00 = total Haber S/ 136,250.00.
A5: 2 | B5: ="Las ventas del mes fueron S/ "&TEXT('Estados Financieros'!C6,"#,##0.00")&" y el costo de ventas S/ "&TEXT(-'Estados Financieros'!C7,"#,##0.00")&". La utilidad bruta fue S/ "&TEXT('Estados Financieros'!C8,"#,##0.00")&" (margen bruto "&TEXT('Estados Financieros'!C8/'Estados Financieros'!C6,"0.0%")&")." -> Las ventas del mes fueron S/ 24,000.00 y el costo de ventas S/ 12,000.00. La utilidad bruta fue S/ 12,000.00 (margen bruto 50.0%).
A6: 3 | B6: ="Tras alquiler, depreciación y desvalorización de existencias, el resultado del ejercicio antes de impuesto a la renta es S/ "&TEXT('Estados Financieros'!C15,"#,##0.00")&"." -> Tras alquiler, depreciación y desvalorización de existencias, el resultado del ejercicio antes de impuesto a la renta es S/ 8,750.00.
A7: 4 | B7: ="El total del activo es S/ "&TEXT('Estados Financieros'!C32,"#,##0.00")&", el pasivo S/ "&TEXT('Estados Financieros'!C36,"#,##0.00")&" y el patrimonio S/ "&TEXT('Estados Financieros'!C41,"#,##0.00")&". La ecuación patrimonial cuadra (diferencia S/ "&TEXT('Estados Financieros'!C44,"#,##0.00")&")." -> El total del activo es S/ 94,350.00, el pasivo S/ 23,600.00 y el patrimonio S/ 70,750.00. La ecuación patrimonial cuadra (diferencia S/ 0.00).
A8: 5 | B8: ="Las existencias quedan en S/ "&TEXT('T Contables'!$L$10-'T Contables'!$D$19,"#,##0.00")&" netas de desvalorización (NIC 2) y el equipo de cómputo en S/ "&TEXT('T Contables'!$B$28-'T Contables'!$I$28,"#,##0.00")&" netos de depreciación (NIC 16)." -> Las existencias quedan en S/ 7,000.00 netas de desvalorización (NIC 2) y el equipo de cómputo en S/ 11,750.00 netos de depreciación (NIC 16).
A9: 6 | B9: ="El IGV deja un saldo a favor de S/ "&TEXT('T Contables'!$G$19,"#,##0.00")&": el crédito fiscal del alquiler y de la compra supera al débito fiscal de la venta." -> El IGV deja un saldo a favor de S/ 360.00: el crédito fiscal del alquiler y de la compra supera al débito fiscal de la venta.
A10: 7 | B10: El alquiler pagado por adelantado se difiere en cargas diferidas y solo el mes de octubre llega al resultado; los otros dos meses quedan como gasto pagado por anticipado.
A11: 8 | B11: Limitaciones: no se calculó impuesto a la renta, y los códigos del PCGE deben confirmarse con la versión que use la universidad.

Sheet Fuentes
A1: FUENTES
A3: N° | B3: Fuente | C3: Uso en el trabajo
A4: 1 | B4: Enunciado: Tarea Académica 1 – Caso Práctico, Tercera Parte (UTP) | C4: Datos de la empresa, operaciones, importes y entregables solicitados.
A5: 2 | B5: Plan Contable General Empresarial (PCGE) – MEF / Consejo Normativo de Contabilidad | C5: Códigos y denominaciones de las cuentas del diario y de las T contables.
A6: 3 | B6: SUNAT – Formato 5.2 Libro Diario de Formato Simplificado (Res. de Superintendencia N.° 234-2006/SUNAT y modificatorias) | C6: Estructura de columnas del Libro Diario Simplificado.
A7: 4 | B7: NIC 2 Inventarios | C7: Medición al menor entre costo y valor neto realizable; desvalorización de existencias.
A8: 5 | B8: NIC 16 Propiedades, planta y equipo | C8: Depreciación del equipo de cómputo en línea recta.
A9: 6 | B9: NIC 1 Presentación de estados financieros | C9: Estructura del estado de situación financiera y del estado de resultados.
A10: 7 | B10: TUO de la Ley del IGV (D.S. N.° 055-99-EF) | C10: Tasa del 18% y tratamiento de crédito y débito fiscal.
